Workbook

Sheet info general 
A1: PATIO CORAO HOTEL
A3: No de Habitaciones | C3: 8
A4: Tiene un Roftof en el ultimo piso pero se le debe meter plata para adecuarlo
A5: Un local como para un café en el primero piso
A6: UN SPA en el sotano para alquilar
A7: actualmente compran un desayuno en 45 mil a un operador o proveedor
A8: se paga por el arriendo 46 millones mas IVA
A9: Afinia promedio pagan 9.150.000
A10: agua 1.400.000
A11: Gas 300.000
A12: Intenert y Cable 600.000 promedio
A13: la nomina tienen 7 personas incluidas el gerente general que puede estar alrededor de 24 millones mensual
A14: su mayor proveedor es bookin en una de las pestañas se ve aproximado cuanto vende cada canal , me sacas cuanto se paga x bookin
A15: quiero que me hagas una macro en excel en el que se muestre los 3 escenarios pesimistas , conservador y pesimista
... A20: incluye tambien todos los gastos que aparecen en la pestaña estados

Sheet patio 1
A1: Patio Corao Cartagena
A2: Fechas: 2026/02/01 - 2026/07/03
A3: Moneda : COP
A4: CANAL DE VENTA | B4: 46054 | C4: 46055 | D4: 46056 | E4: 46057 | F4: 46058 | G4: 46059 | H4: 46060 | I4: 46061 | J4: 46062 | K4: 46063 | L4: 46064 | M4: 46065 | N4: 46066 | O4: 46067 | P4: 46068 | Q4: 46069 | R4: 46070 | S4: 46071 | T4: 46072 | U4: 46073 | V4: 46074 | W4: 46075 | X4: 46076 | Y4: 46077 | Z4: 46078 | AA4: 46079 | AB4: 46080 | AC4: 46081 | AD4: 46082 | AE4: 46083 | AF4: 46084 | AG4: 46085 | AH4: 46086 | AI4: 46087 | AJ4: 46088 | AK4: 46089 | AL4: 46090 | AM4: 46091 | AN4: 46092 | AO4: 46093 | AP4: 46094 | AQ4: 46095 | AR4: 46096 | AS4: 46097 | AT4: 46098 | AU4: 46099 | AV4: 46100 | AW4: 46101 | AX4: 46102 | AY4: 46103 | AZ4: 46104 | BA4: 46105 | BB4: 46106 | BC4: 46107 | BD4: 46108 | BE4: 46109 | BF4: 46110 | BG4: 46111 | BH4: 46112 | BI4: 46113 | BJ4: 46114 | BK4: 46115 | BL4: 46116 | BM4: 46117 | BN4: 46118 | BO4: 46119 | BP4: 46120 | BQ4: 46121 | BR4: 46122 | BS4: 46123 | BT4: 46124 | BU4: 46125 | BV4: 46126 | BW4: 46127 | BX4: 46128 | BY4: 46129 | BZ4: 46130 | CA4: 46131 | CB4: 46132 | CC4: 46133 | CD4: 46134 | CE4: 46135 | CF4: 46136 | CG4: 46137 | CH4: 46138 | CI4: 46139 | CJ4: 46140 | CK4: 46141 | CL4: 46142 | CM4: 46143 | CN4: 46144 | CO4: 46145 | CP4: 46146 | CQ4: 46147 | CR4: 46148 | CS4: 46149 | CT4: 46150 | CU4: 46151 | CV4: 46152 | CW4: 46153 | CX4: 46154 | CY4: 46155 | CZ4: 46156 | DA4: 46157 | DB4: 46158 | DC4: 46159 | DD4: 46160 | DE4: 46161 | DF4: 46162 | DG4: 46163 | DH4: 46164 | DI4: 46165 | DJ4: 46166 | DK4: 46167 | DL4: 46168 | DM4: 46169 | DN4: 46170 | DO4: 46171 | DP4: 46172 | DQ4: 46173 | DR4: 46174 | DS4: 46175 | DT4: 46176 | DU4: 46177 | DV4: 46178 | DW4: 46179 | DX4: 46180 | DY4: 46181 | DZ4: 46182 | EA4: 46183 | EB4: 46184 | EC4: 46185 | ED4: 46186 | EE4: 46187 | EF4: 46188 | EG4: 46189 | EH4: 46190 | EI4: 46191 | EJ4: 46192 | EK4: 46193 | EL4: 46194 | EM4: 46195 | EN4: 46196 | EO4: 46197 | EP4: 46198 | EQ4: 46199 | ER4: 46200 | ES4: 46201 | ET4: 46202 | EU4: 46203 | EV4: 46204 | EW4: 46205 | EX4: 46206 | EY4: Totales
A5: Noches | B5: 5 | C5: 6 | D5: 5 | E5: 6 | F5: 7 | G5: 7 | H5: 5 | I5: 7 | J5: 7 | K5: 8 | L5: 8 | M5: 8 | N5: 8 | O5: 8 | P5: 8 | Q5: 8 | R5: 8 | S5: 7 | T5: 7 | U5: 8 | V5: 8 | W5: 6 | X5: 6 | Y5: 5 | Z5: 6 | AA5: 8 | AB5: 7 | AC5: 8 | AD5: 7 | AE5: 4 | AF5: 4 | AG5: 4 | AH5: 4 | AI5: 6 | AJ5: 5 | AK5: 7 | AL5: 7 | AM5: 6 | AN5: 7 | AO5: 8 | AP5: 7 | AQ5: 8 | AR5: 8 | AS5: 7 | AT5: 6 | AU5: 6 | AV5: 6 | AW5: 7 | AX5: 6 | AY5: 5 | AZ5: 1 | BA5: 4 | BB5: 4 | BC5: 7 | BD5: 8 | BE5: 7 | BF5: 6 | BG5: 7 | BH5: 7 | BI5: 6 | BJ5: 8 | BK5: 8 | BL5: 8 | BM5: 6 | BN5: 5 | BO5: 5 | BP5: 5 | BQ5: 5 | BR5: 7 | BS5: 6 | BT5: 4 | BU5: 4 | BV5: 4 | BW5: 3 | BX5: 5 | BY5: 5 | BZ5: 8 | CA5: 5 | CB5: 5 | CC5: 6 | CD5: 1 | CE5: 5 | CF5: 5 | CG5: 6 | CH5: 3 | CI5: 1 | CJ5: 3 | CK5: 5 | CL5: 7 | CM5: 4 | CN5: 5 | CO5: 7 | CP5: 7 | CQ5: 5 | CR5: 2 | CS5: 2 | CT5: 3 | CU5: 6 | CV5: 4 | CW5: 5 | CX5: 3 | CY5: 5 | CZ5: 7 | DA5: 5 | DB5: 5 | DC5: 7 | DD5: 6 | DE5: 6 | DF5: 6 | DG5: 3 | DH5: 5 | DI5: 6 | DJ5: 3 | DK5: 5 | DL5: 5 | DM5: 5 | DN5: 5 | DO5: 6 | DP5: 5 | DQ5: 3 | DR5: 2 | DS5: 3 | DT5: 3 | DU5: 4 | DV5: 5 | DW5: 8 | DX5: 5 | DY5: 2 | DZ5: 4 | EA5: 5 | EB5: 5 | EC5: 2 | ED5: 2 | EE5: 2 | EF5: 0 | EG5: 1 | EH5: 2 | EI5: 2 | EJ5: 2 | EK5: 1 | EL5: 1 | EM5: 1 | EN5: 2 | EO5: 1 | EP5: 1 | EQ5: 2 | ER5: 4 | ES5: 2 | ET5: 2 | EU5: 1 | EV5: 1 | EW5: 4 | EX5: 5 | EY5: 773
A6: Tarifa Promedio | B6: $ 405,445.22 | C6: $ 402,359.72 | D6: $ 415,250.40 | E6: $ 411,028.46 | F6: $ 425,103.14 | G6: $ 439,392.42 | H6: $ 413,343.79 | I6: $ 479,296.60 | J6: $ 449,953.74 | K6: $ 427,667.93 | L6: $ 388,434.44 | M6: $ 428,238.19 | N6: $ 413,248.38 | O6: $ 425,924.19 | P6: $ 489,744.19 | Q6: $ 469,944.29 | R6: $ 409,270.45 | S6: $ 394,042.01 | T6: $ 419,652.17 | U6: $ 426,079.18 | V6: $ 458,021.49 | W6: $ 432,691.59 | X6: $ 441,035.56 | Y6: $ 370,624.30 | Z6: $ 391,927.84 | AA6: $ 461,670.66 | AB6: $ 443,669.89 | AC6: $ 445,332.82 | AD6: $ 463,698.58 | AE6: $ 526,070.46 | AF6: $ 443,955.00 | AG6: $ 443,955.00 | AH6: $ 411,902.81 | AI6: $ 388,743.80 | AJ6: $ 399,506.66 | AK6: $ 442,507.25 | AL6: $ 494,139.71 | AM6: $ 462,059.49 | AN6: $ 476,957.93 | AO6: $ 476,895.63 | AP6: $ 466,960.28 | AQ6: $ 498,571.72 | AR6: $ 510,287.39 | AS6: $ 499,189.39 | AT6: $ 452,797.94 | AU6: $ 453,737.04 | AV6: $ 491,706.96 | AW6: $ 466,717.68 | AX6: $ 471,362.02 | AY6: $ 484,452.42 | AZ6: $ 406,980.00 | BA6: $ 425,837.13 | BB6: $ 417,692.13 | BC6: $ 488,954.89 | BD6: $ 497,808.97 | BE6: $ 525,785.22 | BF6: $ 465,707.77 | BG6: $ 637,249.94 | BH6: $ 637,248.94 | BI6: $ 593,360.46 | BJ6: $ 603,211.59 | BK6: $ 604,809.09 | BL6: $ 602,558.09 | BM6: $ 724,677.63 | BN6: $ 658,425.11 | BO6: $ 412,693.56 | BP6: $ 398,853.56 | BQ6: $ 416,201.83 | BR6: $ 468,210.31 | BS6: $ 475,332.03 | BT6: $ 323,203.67 | BU6: $ 336,840.67 | BV6: $ 380,561.17 | BW6: $ 368,431.72 | BX6: $ 325,169.28 | BY6: $ 496,458.32 | BZ6: $ 458,191.18 | CA6: $ 470,585.46 | CB6: $ 473,281.07 | CC6: $ 505,505.89 | CD6: $ 354,467.00 | CE6: $ 207,407.27 | CF6: $ 213,847.87 | CG6: $ 264,668.50 | CH6: $ 393,088.56 | CI6: $ 373,350.67 | CJ6: $ 415,404.28 | CK6: $ 388,633.57 | CL6: $ 409,251.38 | CM6: $ 471,325.59 | CN6: $ 477,701.93 | CO6: $ 400,071.99 | CP6: $ 400,598.37 | CQ6: $ 424,861.11 | CR6: $ 524,254.50 | CS6: $ 335,928.33 | CT6: $ 374,840.76 | CU6: $ 365,039.38 | CV6: $ 386,396.65 | CW6: $ 318,174.84 | CX6: $ 426,243.73 | CY6: $ 395,606.82 | CZ6: $ 400,577.59 | DA6: $ 393,452.62 | DB6: $ 392,826.67 | DC6: $ 390,981.47 | DD6: $ 416,761.83 | DE6: $ 139,727.70 | DF6: $ 420,255.20 | DG6: $ 600,315.62 | DH6: $ 441,469.06 | DI6: $ 417,561.79 | DJ6: $ 540,860.78 | DK6: $ 454,934.87 | DL6: $ 371,321.54 | DM6: $ 372,801.44 | DN6: $ 365,435.47 | DO6: $ 369,685.33 | DP6: $ 395,783.80 | DQ6: $ 420,324.00 | DR6: $ 352,323.50 | DS6: $ 376,121.33 | DT6: $ 358,600.67 | DU6: $ 344,106.50 | DV6: $ 377,852.59 | DW6: $ 414,134.13 | DX6: $ 446,098.40 | DY6: $ 445,960.00 | DZ6: $ 396,591.34 | EA6: $ 396,527.07 | EB6: $ 431,985.47 | EC6: $ 597,497.00 | ED6: $ 597,497.00 | EE6: $ 597,497.00 | EF6: $ - | EG6: $ 624,500.00 | EH6: $ 600,617.00 | EI6: $ 428,622.00 | EJ6: $ 428,622.00 | EK6: $ 384,933.00 | EL6: $ 384,933.00 | EM6: $ - | EN6: $ 205,275.00 | EO6: $ - | EP6: $ 517,687.60 | EQ6: $ 464,118.80 | ER6: $ 484,699.40 | ES6: $ 475,756.80 | ET6: $ 475,756.80 | EU6: $ 735,866.00 | EV6: $ 735,866.00 | EW6: $ 383,346.93 | EX6: $ 525,535.14 | EY6: $ 441,963.31
A7: Ingreso | B7: $ 2,027,226.08 | C7: $ 2,414,158.33 | D7: $ 2,076,252.00 | E7: $ 2,466,170.75 | F7: $ 2,975,721.95 | G7: $ 3,075,746.95 | H7: $ 2,066,718.95 | I7: $ 3,355,076.20 | J7: $ 3,149,676.20 | K7: $ 3,421,343.40 | L7: $ 3,107,475.50 | M7: $ 3,425,905.50 | N7: $ 3,305,987.00 | O7: $ 3,407,393.50 | P7: $ 3,917,953.50 | Q7: $ 3,759,554.34 | R7: $ 3,274,163.62 | S7: $ 2,758,294.07 | T7: $ 2,937,565.20 | U7: $ 3,408,633.43 | V7: $ 3,664,171.89 | W7: $ 2,596,149.53 | X7: $ 2,646,213.33 | Y7: $ 1,853,121.50 | Z7: $ 2,351,567.02 | AA7: $ 3,693,365.25 | AB7: $ 3,105,689.25 | AC7: $ 3,562,662.59 | AD7: $ 3,245,890.08 | AE7: $ 2,104,281.83 | AF7: $ 1,775,820.00 | AG7: $ 1,775,820.00 | AH7: $ 1,647,611.25 | AI7: $ 2,332,462.79 | AJ7: $ 1,997,533.28 | AK7: $ 3,097,550.78 | AL7: $ 3,458,977.95 | AM7: $ 2,772,356.95 | AN7: $ 3,338,705.51 | AO7: $ 3,815,165.04 | AP7: $ 3,268,721.95 | AQ7: $ 3,988,573.79 | AR7: $ 4,082,299.13 | AS7: $ 3,494,325.76 | AT7: $ 2,716,787.62 | AU7: $ 2,722,422.26 | AV7: $ 2,950,241.77 | AW7: $ 3,267,023.77 | AX7: $ 2,828,172.10 | AY7: $ 2,422,262.10 | AZ7: $ 406,980.00 | BA7: $ 1,703,348.50 | BB7: $ 1,670,768.50 | BC7: $ 3,422,684.25 | BD7: $ 3,982,471.75 | BE7: $ 3,680,496.54 | BF7: $ 2,794,246.59 | BG7: $ 4,460,749.58 | BH7: $ 4,460,742.58 | BI7: $ 3,560,162.75 | BJ7: $ 4,825,692.75 | BK7: $ 4,838,472.75 | BL7: $ 4,820,464.75 | BM7: $ 4,348,065.75 | BN7: $ 3,292,125.57 | BO7: $ 2,063,467.81 | BP7: $ 1,994,267.81 | BQ7: $ 2,081,009.17 | BR7: $ 3,277,472.17 | BS7: $ 2,851,992.18 | BT7: $ 1,292,814.67 | BU7: $ 1,347,362.69 | BV7: $ 1,522,244.69 | BW7: $ 1,105,295.17 | BX7: $ 1,625,846.41 | BY7: $ 2,482,291.58 | BZ7: $ 3,665,529.42 | CA7: $ 2,352,927.32 | CB7: $ 2,366,405.34 | CC7: $ 3,033,035.34 | CD7: $ 354,467.00 | CE7: $ 1,037,036.34 | CF7: $ 1,069,239.33 | CG7: $ 1,588,010.99 | CH7: $ 1,179,265.67 | CI7: $ 373,350.67 | CJ7: $ 1,246,212.84 | CK7: $ 1,943,167.83 | CL7: $ 2,864,759.69 | CM7: $ 1,885,302.35 | CN7: $ 2,388,509.64 | CO7: $ 2,800,503.95 | CP7: $ 2,804,188.62 | CQ7: $ 2,124,305.55 | CR7: $ 1,048,509.00 | CS7: $ 671,856.66 | CT7: $ 1,124,522.27 | CU7: $ 2,190,236.27 | CV7: $ 1,545,586.60 | CW7: $ 1,590,874.20 | CX7: $ 1,278,731.20 | CY7: $ 1,978,034.10 | CZ7: $ 2,804,043.10 | DA7: $ 1,967,263.10 | DB7: $ 1,964,133.35 | DC7: $ 2,736,870.31 | DD7: $ 2,500,570.99 | DE7: $ 838,366.19 | DF7: $ 2,521,531.19 | DG7: $ 1,800,946.86 | DH7: $ 2,207,345.28 | DI7: $ 2,505,370.75 | DJ7: $ 1,622,582.33 | DK7: $ 2,274,674.33 | DL7: $ 1,856,607.72 | DM7: $ 1,864,007.22 | DN7: $ 1,827,177.33 | DO7: $ 2,218,112.00 | DP7: $ 1,978,919.00 | DQ7: $ 1,260,972.00 | DR7: $ 704,647.00 | DS7: $ 1,128,364.00 | DT7: $ 1,075,802.00 | DU7: $ 1,376,426.00 | DV7: $ 1,889,262.97 | DW7: $ 3,313,073.00 | DX7: $ 2,230,492.00 | DY7: $ 891,920.00 | DZ7: $ 1,586,365.34 | EA7: $ 1,982,635.33 | EB7: $ 2,159,927.33 | EC7: $ 1,194,994.00 | ED7: $ 1,194,994.00 | EE7: $ 1,194,994.00 | EF7: $ - | EG7: $ 624,500.00 | EH7: $ 1,201,234.00 | EI7: $ 857,244.00 | EJ7: $ 857,244.00 | EK7: $ 384,933.00 | EL7: $ 384,933.00 | EM7: $ - | EN7: $ 410,550.00 | EO7: $ - | EP7: $ 517,687.60 | EQ7: $ 928,237.60 | ER7: $ 1,938,797.60 | ES7: $ 951,513.60 | ET7: $ 951,513.60 | EU7: $ 735,866.00 | EV7: $ 735,866.00 | EW7: $ 1,533,387.73 | EX7: $ 2,627,675.71 | EY7: $ 341,637,641.15
A8: % Ocupación neta | B8: %62.5 | C8: %75.0 | D8: %62.5 | E8: %75.0 | F8: %87.5 | G8: %87.5 | H8: %62.5 | I8: %87.5 | J8: %87.5 | K8: %100.0 | L8: %100.0 | M8: %100.0 | N8: %100.0 | O8: %100.0 | P8: %100.0 | Q8: %100.0 | R8: %100.0 | S8: %87.5 | T8: %87.5 | U8: %100.0 | V8: %100.0 | W8: %75.0 | X8: %75.0 | Y8: %62.5 | Z8: %75.0 | AA8: %100.0 | AB8: %87.5 | AC8: %100.0 | AD8: %87.5 | AE8: %50.0 | AF8: %50.0 | AG8: %50.0 | AH8: %50.0 | AI8: %75.0 | AJ8: %62.5 | AK8: %87.5 | AL8: %87.5 | AM8: %75.0 | AN8: %87.5 | AO8: %100.0 | AP8: %87.5 | AQ8: %100.0 | AR8: %100.0 | AS8: %87.5 | AT8: %75.0 | AU8: %75.0 | AV8: %75.0 | AW8: %87.5 | AX8: %75.0 | AY8: %62.5 | AZ8: %12.5 | BA8: %50.0 | BB8: %50.0 | BC8: %87.5 | BD8: %100.0 | BE8: %87.5 | BF8: %75.0 | BG8: %87.5 | BH8: %87.5 | BI8: %75.0 | BJ8: %100.0 | BK8: %100.0 | BL8: %100.0 | BM8: %75.0 | BN8: %62.5 | BO8: %62.5 | BP8: %62.5 | BQ8: %62.5 | BR8: %87.5 | BS8: %75.0 | BT8: %50.0 | BU8: %50.0 | BV8: %50.0 | BW8: %37.5 | BX8: %50.0 | BY8: %62.5 | BZ8: %87.5 | CA8: %62.5 | CB8: %62.5 | CC8: %75.0 | CD8: %12.5 | CE8: %37.5 | CF8: %37.5 | CG8: %50.0 | CH8: %37.5 | CI8: %12.5 | CJ8: %37.5 | CK8: %62.5 | CL8: %87.5 | CM8: %50.0 | CN8: %62.5 | CO8: %87.5 | CP8: %87.5 | CQ8: %62.5 | CR8: %25.0 | CS8: %25.0 | CT8: %37.5 | CU8: %75.0 | CV8: %50.0 | CW8: %50.0 | CX8: %37.5 | CY8: %62.5 | CZ8: %87.5 | DA8: %62.5 | DB8: %62.5 | DC8: %87.5 | DD8: %75.0 | DE8: %62.5 | DF8: %62.5 | DG8: %37.5 | DH8: %62.5 | DI8: %75.0 | DJ8: %37.5 | DK8: %62.5 | DL8: %62.5 | DM8: %62.5 | DN8: %62.5 | DO8: %62.5 | DP8: %50.0 | DQ8: %37.5 | DR8: %25.0 | DS8: %37.5 | DT8: %37.5 | DU8: %50.0 | DV8: %62.5 | DW8: %87.5 | DX8: %62.5 | DY8: %25.0 | DZ8: %50.0 | EA8: %62.5 | EB8: %62.5 | EC8: %25.0 | ED8: %25.0 | EE8: %25.0 | EF8: %0.0 | EG8: %12.5 | EH8: %25.0 | EI8: %25.0 | EJ8: %25.0 | EK8: %12.5 | EL8: %12.5 | EM8: %0.0 | EN8: %12.5 | EO8: %0.0 | EP8: %12.5 | EQ8: %25.0 | ER8: %50.0 | ES8: %25.0 | ET8: %25.0 | EU8: %12.5 | EV8: %12.5 | EW8: %37.5 | EX8: %50.0 | EY8: %61.6
A9: % Ocupación bruta | B9: %62.5 | C9: %75.0 | D9: %62.5 | E9: %75.0 | F9: %87.5 | G9: %87.5 | H9: %62.5 | I9: %87.5 | J9: %87.5 | K9: %100.0 | L9: %100.0 | M9: %100.0 | N9: %100.0 | O9: %100.0 | P9: %100.0 | Q9: %100.0 | R9: %100.0 | S9: %87.5 | T9: %87.5 | U9: %100.0 | V9: %100.0 | W9: %75.0 | X9: %75.0 | Y9: %62.5 | Z9: %75.0 | AA9: %100.0 | AB9: %87.5 | AC9: %100.0 | AD9: %87.5 | AE9: %50.0 | AF9: %50.0 | AG9: %50.0 | AH9: %50.0 | AI9: %75.0 | AJ9: %62.5 | AK9: %87.5 | AL9: %87.5 | AM9: %75.0 | AN9: %87.5 | AO9: %100.0 | AP9: %87.5 | AQ9: %100.0 | AR9: %100.0 | AS9: %87.5 | AT9: %75.0 | AU9: %75.0 | AV9: %75.0 | AW9: %87.5 | AX9: %75.0 | AY9: %62.5 | AZ9: %12.5 | BA9: %50.0 | BB9: %50.0 | BC9: %87.5 | BD9: %100.0 | BE9: %87.5 | BF9: %75.0 | BG9: %87.5 | BH9: %87.5 | BI9: %75.0 | BJ9: %100.0 | BK9: %100.0 | BL9: %100.0 | BM9: %75.0 | BN9: %62.5 | BO9: %62.5 | BP9: %62.5 | BQ9: %62.5 | BR9: %87.5 | BS9: %75.0 | BT9: %50.0 | BU9: %50.0 | BV9: %50.0 | BW9: %37.5 | BX9: %62.5 | BY9: %62.5 | BZ9: %100.0 | CA9: %62.5 | CB9: %62.5 | CC9: %75.0 | CD9: %12.5 | CE9: %62.5 | CF9: %62.5 | CG9: %75.0 | CH9: %37.5 | CI9: %12.5 | CJ9: %37.5 | CK9: %62.5 | CL9: %87.5 | CM9: %50.0 | CN9: %62.5 | CO9: %87.5 | CP9: %87.5 | CQ9: %62.5 | CR9: %25.0 | CS9: %25.0 | CT9: %37.5 | CU9: %75.0 | CV9: %50.0 | CW9: %62.5 | CX9: %37.5 | CY9: %62.5 | CZ9: %87.5 | DA9: %62.5 | DB9: %62.5 | DC9: %87.5 | DD9: %75.0 | DE9: %75.0 | DF9: %75.0 | DG9: %37.5 | DH9: %62.5 | DI9: %75.0 | DJ9: %37.5 | DK9: %62.5 | DL9: %62.5 | DM9: %62.5 | DN9: %62.5 | DO9: %75.0 | DP9: %62.5 | DQ9: %37.5 | DR9: %25.0 | DS9: %37.5 | DT9: %37.5 | DU9: %50.0 | DV9: %62.5 | DW9: %100.0 | DX9: %62.5 | DY9: %25.0 | DZ9: %50.0 | EA9: %62.5 | EB9: %62.5 | EC9: %25.0 | ED9: %25.0 | EE9: %25.0 | EF9: %0.0 | EG9: %12.5 | EH9: %25.0 | EI9: %25.0 | EJ9: %25.0 | EK9: %12.5 | EL9: %12.5 | EM9: %12.5 | EN9: %25.0 | EO9: %12.5 | EP9: %12.5 | EQ9: %25.0 | ER9: %50.0 | ES9: %25.0 | ET9: %25.0 | EU9: %12.5 | EV9: %12.5 | EW9: %50.0 | EX9: %62.5 | EY9: %63.2
A14: Patio Corao Cartagena
A15: Fechas: 2026/02 - 2026/02
A16: Moneda : COP
A17: CANAL DE VENTA | B17: Febrero | C17: Marzo | D17: Abril | E17: Mayo | F17: Junio | G17: Julio | H17: Agosto | I17: Totales
A18: Noches | B18: 195 | C18: 186 | D18: 154 | E18: 151 | F18: 77 | G18: 124 | H18: 158 | I18: 1045
A19: Tarifa Promedio | B19: $ 429,763.88 | C19: $ 482,180.08 | D19: $ 457,158.81 | E19: $ 398,547.37 | F19: $ 424,261.70 | G19: $ 578,234.17 | H19: $ 540,702.72 | I19: $ 472,605.53
A20: Ingreso | B20: $ 83,803,956.84 | C20: $ 89,685,494.00 | D20: $ 70,402,456.45 | E20: $ 60,180,653.46 | F20: $ 32,668,150.97 | G20: $ 71,701,037.29 | H20: $ 85,431,029.06 | I20: $ 493,872,778.07
A21: % Ocupación neta | B21: %87.1 | C21: %75.0 | D21: %60.8 | E21: %58.9 | F21: %30.4 | G21: %48.8 | H21: %63.7 | I21: %60.7
A22: % Ocupación bruta | B22: %87.1 | C22: %75.0 | D22: %64.2 | E22: %60.9 | F22: %32.1 | G22: %50.0 | H22: %63.7 | I22: %61.8

Sheet patio 2
A1: Patio Corao Cartagena
A2: Moneda : COP - Sin impuestos
A3: Feb-2026 - Aug-2026
A4: Producción de canal por pais
C5: Pais | D5: Noches | E5: Oc. Net % | F5: ADR | G5: Estancia Promedio | H5: Ventana Reserva Promedio
B6: BOOKING | C6: TOTAL | D6: 792 | E6: 100.00% | F6: 485549.24 | G6: 2.57 | H6: 40.49
C7: Colombia | D7: 61 | E7: 7.70% | F7: 453749.43 | G7: 1.83 | H7: 30.37
C8: Bélgica | D8: 19 | E8: 2.40% | F8: 572170.93 | G8: 2.5 | H8: 32.75
C9: Francia | D9: 82 | E9: 10.35% | F9: 498866.77 | G9: 2 | H9: 28.49
C10: Perú | D10: 18 | E10: 2.27% | F10: 434308.28 | G10: 2.57 | H10: 5.14
C11: Estados Unidos | D11: 70 | E11: 8.84% | F11: 611939.97 | G11: 2.69 | H11: 24.27
C12: España | D12: 107 | E12: 13.51% | F12: 448241.79 | G12: 2.06 | H12: 30.5
C13: Desconocido | D13: 73 | E13: 9.22% | F13: 558290.47 | G13: 2.41 | H13: 115.97
C14: Brasil | D14: 66 | E14: 8.33% | F14: 433217.41 | G14: 2.75 | H14: 29.04
C15: Chile | D15: 14 | E15: 1.77% | F15: 464816.21 | G15: 2.8 | H15: 7.8
C16: Grecia | D16: 8 | E16: 1.01% | F16: 434836.25 | G16: 2.67 | H16: 37
C17: Costa Rica | D17: 2 | E17: 0.25% | F17: 315630 | G17: 2 | H17: 2
C18: Irlanda | D18: 6 | E18: 0.76% | F18: 349393.5 | G18: 1.5 | H18: 51.75
C19: Suiza | D19: 19 | E19: 2.40% | F19: 524023 | G19: 2.71 | H19: 2.14
C20: Polonia | D20: 9 | E20: 1.14% | F20: 495447.78 | G20: 1.8 | H20: 2.8
C21: Guayana Francesa | D21: 3 | E21: 0.38% | F21: 303515.33 | G21: 3 | H21: 4
C22: Argentina | D22: 30 | E22: 3.79% | F22: 456279.18 | G22: 3.75 | H22: 49.13
C23: Canadá | D23: 14 | E23: 1.77% | F23: 503545.64 | G23: 2.33 | H23: 16.5
C24: Alemania | D24: 30 | E24: 3.79% | F24: 461000.47 | G24: 2.31 | H24: 33.92
C25: Reino Unido | D25: 38 | E25: 4.80% | F25: 446423.45 | G25: 2 | H25: 25.11
C26: Mónaco | D26: 1 | E26: 0.13% | F26: 455175 | G26: 1 | H26: 1
C27: Italia | D27: 21 | E27: 2.65% | F27: 534057.05 | G27: 1.91 | H27: 69.55
C28: Países Bajos | D28: 28 | E28: 3.54% | F28: 487069.54 | G28: 2 | H28: 79.5
C29: Australia | D29: 18 | E29: 2.27% | F29: 415391.39 | G29: 2.57 | H29: 39.43
C30: Emiratos Arabes Unidos | D30: 3 | E30: 0.38% | F30: 481029.33 | G30: 3 | H30: 31
C31: Finlandia | D31: 4 | E31: 0.51% | F31: 619500 | G31: 4 | H31: 10
C32: Croacia | D32: 4 | E32: 0.51% | F32: 294400 | G32: 4 | H32: 14
C33: México | D33: 19 | E33: 2.40% | F33: 460185.68 | G33: 2.38 | H33: 35.38
C34: Aruba | D34: 4 | E34: 0.51% | F34: 542281.5 | G34: 4 | H34: 56
C35: Austria | D35: 2 | E35: 0.25% | F35: 283072.5 | G35: 2 | H35: 17
C36: Japón | D36: 2 | E36: 0.25% | F36: 502165 | G36: 2 | H36: 40
C37: Luxemburgo | D37: 3 | E37: 0.38% | F37: 437325 | G37: 3 | H37: 94
C38: Liechtenstein | D38: 3 | E38: 0.38% | F38: 695523.67 | G38: 3 | H38: 90
C39: Afganistán | D39: 3 | E39: 0.38% | F39: 886225 | G39: 3 | H39: 137
C40: Portugal | D40: 8 | E40: 1.01% | F40: 649577.5 | G40: 4 | H40: 134
...

Sheet Tipos de Hab
A1: Patio Corao Cartagena
A2: Feb-2026 - Sep-2026
A3: Lead Time
C5: T. Habitación | D5: Reservaciones | E5: Entre 1 y 3 Noches | F5: Entre 4 y 7 Noches | G5: Entre 7 y 15 Noches | H5: Mayor a 15 Noches
B6: BDC | C6: TOTAL | D6: 359 | E6: 306 | F6: 51 | G6: 2 | H6: 0
C7: KING D TINA+JACUZZI | D7: 56 | E7: 50 | F7: 6 | G7: 0 | H7: 0
C8: DBL Y KING+TINA+BALCON | D8: 24 | E8: 17 | F8: 6 | G8: 1 | H8: 0
C9: 2DBLES+TINA+BALCON CON VISTA | D9: 40 | E9: 34 | F9: 6 | G9: 0 | H9: 0
C10: 2DBLES+TINA+BALCON SIN VISTA | D10: 32 | E10: 28 | F10: 4 | G10: 0 | H10: 0
C11: KIND D BALCON+TINA | D11: 28 | E11: 25 | F11: 3 | G11: 0 | H11: 0
C12: KING D BALCON | D12: 50 | E12: 44 | F12: 6 | G12: 0 | H12: 0
C13: DOBLE ESTANDAR | D13: 129 | E13: 108 | F13: 20 | G13: 1 | H13: 0
B14: DEFAULT | C14: TOTAL | D14: 41 | E14: 38 | F14: 3 | G14: 0 | H14: 0
C15: KING D TINA+JACUZZI | D15: 5 | E15: 5 | F15: 0 | G15: 0 | H15: 0
C16: DBL Y KING+TINA+BALCON | D16: 4 | E16: 4 | F16: 0 | G16: 0 | H16: 0
C17: 2DBLES+TINA+BALCON CON VISTA | D17: 7 | E17: 6 | F17: 1 | G17: 0 | H17: 0
C18: 2DBLES+TINA+BALCON SIN VISTA | D18: 4 | E18: 4 | F18: 0 | G18: 0 | H18: 0
C19: KIND D BALCON+TINA | D19: 8 | E19: 6 | F19: 2 | G19: 0 | H19: 0
C20: KING D BALCON | D20: 8 | E20: 8 | F20: 0 | G20: 0 | H20: 0
C21: DOBLE ESTANDAR | D21: 5 | E21: 5 | F21: 0 | G21: 0 | H21: 0
B22: EXP | C22: TOTAL | D22: 46 | E22: 34 | F22: 12 | G22: 0 | H22: 0
C23: KING D TINA+JACUZZI | D23: 5 | E23: 5 | F23: 0 | G23: 0 | H23: 0
C24: DBL Y KING+TINA+BALCON | D24: 7 | E24: 3 | F24: 4 | G24: 0 | H24: 0
C25: 2DBLES+TINA+BALCON CON VISTA | D25: 7 | E25: 6 | F25: 1 | G25: 0 | H25: 0
C26: 2DBLES+TINA+BALCON SIN VISTA | D26: 8 | E26: 5 | F26: 3 | G26: 0 | H26: 0
C27: KIND D BALCON+TINA | D27: 6 | E27: 4 | F27: 2 | G27: 0 | H27: 0
C28: KING D BALCON | D28: 9 | E28: 8 | F28: 1 | G28: 0 | H28: 0
C29: DOBLE ESTANDAR | D29: 4 | E29: 3 | F29: 1 | G29: 0 | H29: 0
B30: ABB | C30: TOTAL | D30: 6 | E30: 6 | F30: 0 | G30: 0 | H30: 0
C31: KING D TINA+JACUZZI | D31: 2 | E31: 2 | F31: 0 | G31: 0 | H31: 0
C32: DBL Y KING+TINA+BALCON | D32: 0 | E32: 0 | F32: 0 | G32: 0 | H32: 0
C33: 2DBLES+TINA+BALCON CON VISTA | D33: 1 | E33: 1 | F33: 0 | G33: 0 | H33: 0
C34: 2DBLES+TINA+BALCON SIN VISTA | D34: 0 | E34: 0 | F34: 0 | G34: 0 | H34: 0
C35: KIND D BALCON+TINA | D35: 3 | E35: 3 | F35: 0 | G35: 0 | H35: 0
C36: KING D BALCON | D36: 0 | E36: 0 | F36: 0 | G36: 0 | H36: 0
C37: DOBLE ESTANDAR | D37: 0 | E37: 0 | F37: 0 | G37: 0 | H37: 0
B38: HBD | C38: TOTAL | D38: 2 | E38: 2 | F38: 0 | G38: 0 | H38: 0
C39: KING D TINA+JACUZZI | D39: 0 | E39: 0 | F39: 0 | G39: 0 | H39: 0
C40: DBL Y KING+TINA+BALCON | D40: 0 | E40: 0 | F40: 0 | G40: 0 | H40: 0
C41: 2DBLES+TINA+BALCON CON VISTA | D41: 0 | E41: 0 | F41: 0 | G41: 0 | H41: 0
...

Sheet estados
A1: GRUPO HOTELERO MEXTIZO S.A.S. — ESTADO DE RESULTADOS (a 31 diciembre 2025)
A2: Fuente: PDF cargado por el usuario — PATIO CORAO ESTADOS DE RESULTADOS.pdf
A4: INGRESOS OPERACIONALES
A5: Hospedaje Nacional | B5: 45759421
A6: Hospedaje Extranjero | B6: 231115754
A7: Ventas Minibar | B7: 0
A8: Alquileres para Eventos | B8: 300000
A9: TOTAL INGRESOS OPERACIONALES | B9: =SUM(B5:B8) -> 277175175
A11: COSTO DE VENTA Y SERVICIO
A12: Costo Minibar | B12: 2626899
A13: Comisión Canales de Venta | B13: 18993718
A14: Energía Eléctrica | B14: 41286380
A15: Arrendamiento | B15: 374923000
A16: Lavandería | B16: 1288000
A17: Servicio Agua y Alcantarillado | B17: 9329600
A18: Servicio de Gas | B18: 2278509
A19: Elementos de Aseo y Cafetería | B19: 31560081
A20: TOTAL COSTO DE VENTA Y SERVICIO | B20: =SUM(B12:B19) -> 482286187
A22: RESULTADO BRUTO | B22: =B9-B20 -> -205111012
A24: GASTOS OPERACIONALES
A25: Gastos de Personal (5105) | B25: 94614793
A26: Honorarios | B26: 2556100
A27: Impuestos | B27: 2032000
A28: Seguros | B28: 714000
A29: Servicios (5135) | B29: 12934479
A30: Gastos Legales | B30: 747000
A31: Mantenimiento y Reparaciones | B31: 10848268
A32: Adecuación e Instalación | B32: 4733217
A33: Diversos | B33: 5679921
A34: Gastos de Personal (5205) | B34: 80188289
A35: Servicios (5235) | B35: 1507052
A36: TOTAL GASTOS OPERACIONALES | B36: =SUM(B25:B35) -> 216555119
A38: RESULTADO OPERACIONAL | B38: =B22-B36 -> -421666131
A40: INGRESOS Y GASTOS NO OPERACIONALES
A41: Diversos (ingreso) | B41: 270526
A42: Financieros (gasto) | B42: 9928965
A44: RESULTADO ANTES DE IMPUESTOS | B44: =B38+B41-B42 -> -431324570

Sheet Supuestos
A1: PATIO CORAO HOTEL - SUPUESTOS DEL MODELO
A2: Todas las celdas azules son editables. Cifras en COP.
A4: 1. DATOS DEL HOTEL
A5: No. de Habitaciones | B5: 8
A6: Días por mes (estándar) | B6: 30
A7: Room-noches disponibles / mes | B7: =B5*B6 -> 240
A9: 2. ESCENARIOS DE OCUPACIÓN Y TARIFA
A10: Escenario | B10: Pesimista | C10: Conservador | D10: Optimista
A11: % Ocupación | B11: 0.5 | C11: 0.7 | D11: 0.8
A12: Tarifa Promedio (ADR) | B12: 490000 | C12: 650000 | D12: 800000
A13: Room-noches ocupadas / mes | B13: =$B$7*B11 -> 120 | C13: =$B$7*C11 -> 168 | D13: =$B$7*D11 -> 192
A15: 3. COSTOS FIJOS MENSUALES
A16: Arrendamiento (neto, sin IVA) | B16: 46000000 | C16: Fuente: info general A8. IVA 19% es descontable y no se registra como gasto en el P&G
A17: IVA arriendo (referencial, solo caja) | B17: =B16*0.19 -> 8740000
A18: Energía Eléctrica (Afinia) | B18: 9150000
A19: Agua y Alcantarillado | B19: 1400000
A20: Gas | B20: 300000
A21: Internet y Cable | B21: 600000
A22: Nómina (4 personas incl. Gerente General) | B22: 12000000
A23: TOTAL COSTOS FIJOS MENSUALES | B23: =B16+B18+B19+B20+B21+B22 -> 69450000
A25: 4. COSTOS VARIABLES POR VENTA
A26: Costo Desayuno por hab-noche ocupada | B26: 35000
A27: % Participación Booking sobre ventas | B27: =_xlfn.NUMBERVALUE(SUBSTITUTE('patio 2'!I103,"$",""),".",",")/_xlfn.NUMBERVALUE(SUBSTITUTE('patio 2'!I113,"$",""),".",",") -> 0.74436575 | C27: Fuente: patio 2, producción por canal (Booking $257.0MM / Total $345.3MM)
A28: % Comisión Booking.com | B28: 0.18 | C28: Tarifa estándar Booking Latam — ajustable según contrato real
A30: 5. COMERCIALIZACIÓN GEH SUITES
A31: Fee fijo mensual | B31: 3000000
A32: % Variable sobre ventas totales | B32: 0.02 | C32: Editable: porcentaje modificable según negociación
A34: 6. RATIOS DE GASTOS (Estado de Resultados 2025, Grupo Hotelero Mextizo S.A.S. — PDF)
A35: Rubro | B35: Histórico 2025 ($) | C35: % sobre Ingresos | D35: Nota
A36: Ingresos Operacionales Totales 2025 (base) | B36: =estados!B9 -> 277175175 | C36: 1
A37: Costo Minibar | B37: =estados!B12 -> 2626899 | C37: =B37/$B$36 -> 0.0094773964
A38: Lavandería | B38: =estados!B16 -> 1288000 | C38: =B38/$B$36 -> 0.0046468808
A39: Aseo y Cafetería | B39: =estados!B19 -> 31560081 | C39: =B39/$B$36 -> 0.1138633
A40: Honorarios | B40: =estados!B26 -> 2556100 | C40: =B40/$B$36 -> 0.0092219659
A41: Impuestos (ICA, etc.) | B41: =estados!B27 -> 2032000 | C41: =B41/$B$36 -> 0.0073311039
A42: Seguros | B42: =estados!B28 -> 714000 | C42: =B42/$B$36 -> 0.0025759883
A43: Servicios Administrativos | B43: =estados!B29+estados!B35 -> 14441531 | C43: =B43/$B$36 -> 0.052102541
A44: Gastos Legales | B44: =estados!B30 -> 747000 | C44: =B44/$B$36 -> 0.0026950466
A45: Mantenimiento y Reparaciones | B45: =estados!B31 -> 10848268 | C45: =B45/$B$36 -> 0.039138671
A46: Adecuación e Instalación (*posible no recurrente) | B46: =estados!B32 -> 4733217 | C46: =B46/$B$36 -> 0.017076627
...

Sheet PyG Hospedaje
A1: PATIO CORAO HOTEL - P&G HOSPEDAJE (Mensual) | B1: PATIO CORAO HOTEL - P&G HOSPEDAJE (Mensual)
A2: Solo ingresos por habitaciones — 3 escenarios. Cifras en COP. | B2: Solo ingresos por habitaciones — 3 escenarios. Cifras en COP.
A4: Escenario | B4: Escenario | C4: =Supuestos!B10 -> Pesimista | E4: =Supuestos!C10 -> Conservador | G4: =Supuestos!D10 -> Optimista
B5: PATIO CORA0 ( Estado P y G ) | G5: 240
B6: DETALLE | C6: PESIMISTA | E6: CONSERVADOR | G6: OPTIMISTA
C7: MES | D7: AÑO | E7: MES | F7: AÑO | G7: MES | H7: AÑO
A8: % Ocupación | B8: % Ocupación | C8: 0.5 | D8: =+C8 -> 0.5 | E8: 0.7 | F8: =+E8 -> 0.7 | G8: 0.75 | H8: =+G8 -> 0.75
A9: Tarifa Promedio (ADR) | B9: Tarifa Promedio (ADR) | C9: 500000 | D9: 500000 | E9: 700000 | F9: =+E9 -> 700000 | G9: 790000 | H9: =+G9 -> 790000
A10: Room-noches Ocupadas | B10: Room-noches Ocupadas | C10: =+G5*C8 -> 120 | D10: =+C10*12 -> 1440 | E10: =+G5*E8 -> 168 | F10: =+E10*12 -> 2016 | G10: =+G5*G8 -> 180 | H10: =+G10*12 -> 2160
A12: INGRESOS | B12: INGRESOS | C12: =+C14+C15+C16+C17 -> 67500000 | D12: =+C12*12 -> 810000000 | E12: =+E14+E15+E16+E17 -> 125100000 | F12: =+E12*12 -> 1501200000 | G12: =+G14+G15+G16+G17 -> 149700000 | H12: =+G12*12 -> 1796400000
A14: Ingresos por Venta de Hospedaje | B14: Ingresos por Venta de Hospedaje | C14: =+C9*C10 -> 60000000 | D14: =+C14*12 -> 720000000 | E14: =+E9*E10 -> 117600000 | F14: =+E14*12 -> 1411200000 | G14: =+G9*G10 -> 142200000 | H14: =+G14*12 -> 1706400000
B15: Ingreso Rooftop (mensual)
B16: Ingreso Local Café (mensual, arriendo) | C16: 6000000 | D16: =+C16*12 -> 72000000 | E16: =+C16 -> 6000000 | F16: =+E16*12 -> 72000000 | G16: =+C16 -> 6000000 | H16: =+G16*12 -> 72000000
B17: Ingreso SPA (mensual, arriendo) | C17: 1500000 | D17: =+C17*12 -> 18000000 | E17: =+C17 -> 1500000 | F17: =+E17*12 -> 18000000 | G17: =+C17 -> 1500000 | H17: =+G17*12 -> 18000000
A18: COSTOS DIRECTOS | B18: COSTOS DIRECTOS
A19: Gasto por Comisión Booking.com (18%) | B19: Gasto por Comisión Booking.com (18%) | C19: =C14*Supuestos!$B$27*Supuestos!$B$28 -> 8039150.1 | D19: =+C19*12 -> 96469801 | E19: =E14*Supuestos!$B$27*Supuestos!$B$28 -> 15756734 | F19: =+E19*12 -> 1.8908081e+08 | G19: =G14*Supuestos!$B$27*Supuestos!$B$28 -> 19052786 | H19: =+G19*12 -> 2.2863343e+08
A20: Costo de Desayuno | B20: Costo de Desayuno | C20: =C10*Supuestos!$B$26 -> 4200000 | D20: =+C20*12 -> 50400000 | E20: =E10*Supuestos!$B$26 -> 5880000 | F20: =+E20*12 -> 70560000 | G20: =G10*Supuestos!$B$26 -> 6300000 | H20: =+G20*12 -> 75600000
A21: Costo de Lavandería | B21: Costo de Lavandería | C21: 1800000 | D21: =+C21*12 -> 21600000 | E21: =E14*Supuestos!$C$38 -> 546473.18 | F21: =+E21*12 -> 6557678.2 | G21: =G14*Supuestos!$C$38 -> 660786.45 | H21: =+G21*12 -> 7929437.4
A22: Costo de Aseo y Cafetería | B22: Costo de Aseo y Cafetería | C22: 5200000 | D22: =+C22*12 -> 62400000 | E22: =+(C22*15%)+C22 -> 5980000 | F22: =+E22*12 -> 71760000 | G22: =+(E22*5%)+E22 -> 6279000 | H22: =+G22*12 -> 75348000
A23: Gasto de Energía Eléctrica | B23: Gasto de Energía Eléctrica | C23: 8500000 | D23: =+C23*12 -> 102000000 | E23: =+(C23*5%)+C23 -> 8925000 | F23: =+E23*12 -> 107100000 | G23: =+(E23*5%)+E23 -> 9371250 | H23: =+G23*12 -> 112455000
A24: Gasto de Arrendamiento | B24: Gasto de Arrendamiento | C24: =Supuestos!$B$16 -> 46000000 | D24: =+C24*12 -> 552000000 | E24: =Supuestos!$B$16 -> 46000000 | F24: =+E24*12 -> 552000000 | G24: =Supuestos!$B$16 -> 46000000 | H24: =+G24*12 -> 552000000
A25: Gasto de Agua y Alcantarillado | B25: Gasto de Agua y Alcantarillado | C25: =Supuestos!$B$19 -> 1400000 | D25: =+C25*12 -> 16800000 | E25: =+(C25*5%)+C25 -> 1470000 | F25: =+E25*12 -> 17640000 | G25: =+(E25*5%)+E25 -> 1543500 | H25: =+G25*12 -> 18522000
A26: Gasto de Gas | B26: Gasto de Gas | C26: 150000 | D26: =+C26*12 -> 1800000 | E26: =+(C26*5%)+C26 -> 157500 | F26: =+E26*12 -> 1890000 | G26: =+(E26*5%)+E26 -> 165375 | H26: =+G26*12 -> 1984500
A27: Gasto de Internet y Cable | B27: Gasto de Internet y Cable | C27: 500000 | D27: =+C27*12 -> 6000000 | E27: 500000 | F27: =+E27*12 -> 6000000 | G27: 500000 | H27: =+G27*12 -> 6000000
A28: TOTAL COSTOS DIRECTOS | B28: TOTAL COSTOS DIRECTOS | C28: =SUM(C19:C27) -> 75789150 | D28: =+C28*12 -> 9.094698e+08 | E28: =SUM(E19:E27) -> 85215707 | F28: =+E28*12 -> 1.0225885e+09 | G28: =SUM(G19:G27) -> 89872697 | H28: =+G28*12 -> 1.0784724e+09
A30: UTILIDAD BRUTA | B30: UTILIDAD BRUTA | C30: =C12-C28 -> -8289150.1 | D30: =D12-D28 -> -99469801 | E30: =E12-E28 -> 39884293 | F30: =F12-F28 -> 4.7861151e+08 | G30: =G12-G28 -> 59827303 | H30: =H12-H28 -> 7.1792763e+08
A32: GASTOS OPERACIONALES | B32: GASTOS OPERACIONALES
A33: Gasto de Nómina (7 personas) | B33: Gasto de Nómina (4 personas) | C33: 12000000 | D33: =+C33*12 -> 144000000 | E33: =+C33 -> 12000000 | F33: =+E33*12 -> 144000000 | G33: 12000000 | H33: =+G33*12 -> 144000000
B34: Gastos Nomina Practicantes (2) | C34: 3000000 | D34: =+C34*12 -> 36000000 | E34: 3000000 | F34: =+E34*12 -> 36000000 | G34: 3000000 | H34: =+G34*12 -> 36000000
A35: Gasto de Honorarios | B35: Gasto de Honorarios | C35: =C14*Supuestos!$C$40 -> 553317.95 | D35: =+C35*12 -> 6639815.4 | E35: =E14*Supuestos!$C$40 -> 1084503.2 | F35: =+E35*12 -> 13014038 | G35: =G14*Supuestos!$C$40 -> 1311363.5 | H35: =+G35*12 -> 15736363
A36: Gasto de Impuestos (ICA, etc.) | B36: Gasto de Impuestos (ICA, etc.) | C36: =C14*Supuestos!$C$41 -> 439866.23 | D36: =+C36*12 -> 5278394.8 | E36: =E14*Supuestos!$C$41 -> 862137.82 | F36: =+E36*12 -> 10345654 | G36: =G14*Supuestos!$C$41 -> 1042483 | H36: =+G36*12 -> 12509796
A37: Gasto de Seguros | B37: Gasto de Seguros | C37: =C14*Supuestos!$C$42 -> 154559.3 | D37: =+C37*12 -> 1854711.6 | E37: =E14*Supuestos!$C$42 -> 302936.22 | F37: =+E37*12 -> 3635234.6 | G37: =G14*Supuestos!$C$42 -> 366305.53 | H37: =+G37*12 -> 4395666.4
A38: Gasto de Servicios Administrativos | B38: Gasto de Servicios Administrativos | C38: 1200000 | D38: =+C38*12 -> 14400000 | E38: =+C38+(C38*5%) -> 1260000 | F38: =+E38*12 -> 15120000 | G38: =+E38+(E38*5%) -> 1323000 | H38: =+G38*12 -> 15876000
A39: Gasto de Asesoría Legal | B39: Gasto de Asesoría Legal | C39: =C14*Supuestos!$C$44 -> 161702.79 | D39: =+C39*12 -> 1940433.5 | E39: =E14*Supuestos!$C$44 -> 316937.47 | F39: =+E39*12 -> 3803249.7 | G39: =G14*Supuestos!$C$44 -> 383235.62 | H39: =+G39*12 -> 4598827.4
A40: Gasto de Mantenimiento y Reparaciones | B40: Gasto de Mantenimiento y Reparaciones | C40: 1040000 | D40: =+C40*12 -> 12480000 | E40: =+(C40*5%)+C40 -> 1092000 | F40: =+E40*12 -> 13104000 | G40: =+(E40*5%)+E40 -> 1146600 | H40: =+G40*12 -> 13759200
A41: Gasto de Adecuación e Instalación | B41: Gasto de Adecuación e Instalación | C41: 800000 | D41: =+C41*12 -> 9600000 | E41: =+(C41*5%)+C41 -> 840000 | F41: =+E41*12 -> 10080000 | G41: =+(E41*5%)+E41 -> 882000 | H41: =+G41*12 -> 10584000
A42: Gastos Diversos | B42: Gastos Diversos ( imprevistos ) | C42: 1050000 | D42: =+C42*12 -> 12600000 | E42: =+(C42*5%)+C42 -> 1102500 | F42: =+E42*12 -> 13230000 | G42: =+(E42*5%)+E42 -> 1157625 | H42: =+G42*12 -> 13891500
A43: TOTAL GASTOS OPERACIONALES | B43: TOTAL GASTOS OPERACIONALES | C43: =SUM(C33:C42) -> 20399446 | D43: =SUM(D33:D42) -> 2.4479336e+08 | E43: =SUM(E33:E42) -> 21861015 | F43: =SUM(F33:F42) -> 2.6233218e+08 | G43: =SUM(G33:G42) -> 22612613 | H43: =SUM(H33:H42) -> 2.7135135e+08
A45: EBITDA (UTILIDAD OPERACIONAL) | B45: EBITDA (UTILIDAD OPERACIONAL) | C45: =C30-C43 -> -28688596 | D45: =D30-D43 -> -3.4426316e+08 | E45: =E30-E43 -> 18023278 | F45: =F30-F43 -> 2.1627933e+08 | G45: =G30-G43 -> 37214690 | H45: =H30-H43 -> 4.4657628e+08
A46: Margen EBITDA % | B46: Margen EBITDA % | C46: =C45/C14 -> -0.47814327 | D46: =D45/D14 -> -0.47814327 | E46: =E45/E14 -> 0.15325917 | F46: =F45/F14 -> 0.15325917 | G46: =G45/G14 -> 0.26170668 | H46: =H45/H14 -> 0.26170668
...
